Workbook

Sheet Tasks
A1: Task ID | B1: Phase | C1: Artefact / Script | D1: Task | E1: Type | F1: Design Ref | G1: Depends On | H1: Est. Days | I1: Owner | J1: Status | K1: % Done | L1: Started | M1: Completed | N1: Actual Days | O1: Notes / Blockers
A2: T-001 | B2: 0 Foundations | C2: (environment) | D2: Provision throwaway development database; assert SQL Server 2022 compatibility level and READ_COMMITTED_SNAPSHOT | E2: Environment | F2: PLAN §3 PRE-01 | H2: 0.5 | I2: Opus 5 | J2: Complete | K2: 1 | L2: 46284 | M2: 46284 | N2: 0.25 | O2: Done. testTemplate did not exist on MDE-55TT2J4; 000_prerequisites.sql created it and set compatibility level 160, READ_COMMITTED_SNAPSHOT ON, PAGE_VERIFY CHECKSUM and AUTO_CLOSE OFF. A later run printed "Database [testTemplate] already exists. Reusing it; nothing dropped, nothing recreated." -- create-if-absent and reuse-if-present are both proven. The instance is SQL Server 2025 (17.0.1135.8, Standard Developer Edition), not 2022, so the above-major-16 warning fires on every deployment: see A-01 and BL-018.
A3: T-002 | B3: 0 Foundations | C3: (environment) | D3: Confirm the estate's database role names: applicationRole, readOnlyRole, logsAuditReader, rlsBypassRole | E3: Environment | F3: PLAN §3 PRE-03 | H3: 0.25 | I3: Opus 5 | J3: Complete | K3: 1 | L3: 46284 | M3: 46284 | N3: 0.25 | O3: Renamed across 16 files, 151 occurrences: app_role->applicationRole, readonly_role->readOnlyRole, logs_audit_reader->logsAuditReader. rls_bypass_role->rlsBypassRole was not requested -- renamed for consistency since it is this design's own coinage; trivially reversible. Word-boundary matching used so @read_only and db_owner were untouched; verified nothing collateral changed.
A4: T-003 | B4: 0 Foundations | C4: extended-properties.sql | D4: Run the conventions skill's extended-properties template; verify util.uspSetObjectDescription exists and is re-runnable | E4: Script | F4: DES §21.2 | G4: T-001 | H4: 0.25 | I4: Opus 5 | J4: Complete | K4: 1 | L4: 46284 | M4: 46284 | N4: 0.25 | O4: Done. extended-properties.sql ran clean against MDE-55TT2J4\testTemplate; util.uspSetObjectDescription exists, and a second run reported no change.
A5: T-004 | B5: 0 Foundations | C5: logdBChanges.sql | D5: Run DDL change logging installer; verify with checkDbChangeLogging.sql and logs.uspDdlAuditVerify | E5: Script | F5: DES §21.2 | G5: T-003 | H5: 0.5 | I5: Opus 5 | J5: Complete | K5: 1 | L5: 46284 | M5: 46284 | N5: 0.5 | O5: Done. logdBChanges.sql ran clean. checkDbChangeLogging.sql returns 19 OK/INFO rows and no failures, on the first run and on the second; logs.uspDdlAuditVerify returns 7 OK plus one INFO watermark row. One first-pass deferred-resolution warning: logs.uspDdlAuditVerify references logs.uspRecordExecutionError, which the next installer creates. Harmless in the documented order and not fixable by swapping the two. BL-017.
A6: T-005 | B6: 0 Foundations | C6: logExecutionLogging.sql | D6: Run execution logging installer; confirm the closing report is clean including the owner of schema logs | E6: Script | F6: DES §21.2 | G6: T-004 | H6: 0.5 | I6: Opus 5 | J6: Complete | K6: 1 | L6: 46284 | M6: 46284 | N6: 0.25 | O6: Done. logExecutionLogging.sql ran clean; logs.ExecutionLog and the four logging procedures exist and schema logs is owned by dbo, as the closing report requires. StartDateUtc is DATETIME2 (3) in the database, matching what the procedure template declares.
A7: T-006 | B7: 0 Foundations | C7: permissions.sql | D7: Run the schema permission script; read the catalog report back | E7: Script | F7: DES §21.2 | G7: T-005 | H7: 0.25 | I7: Opus 5 | J7: Complete | K7: 1 | L7: 46284 | M7: 46284 | N7: 0.25 | O7: Done. permissions.sql ran clean and the catalog report reads back. What the report does not say is that the script issues no grant and no deny on SCHEMA::config or SCHEMA::util, so after a complete Phase 0 deployment both are invisible to applicationRole and readOnlyRole with no error anywhere. SCHEMA::auth is deliberate (INV-11); config and util are simply outside the conventions script's model. New gap G-19; 170_permissions.sql (Phase 8) must close config. BL-015.
A8: T-007 | B8: 0 Foundations | C8: (all four installers) | D8: Second full run from the same state; confirm zero change and zero output — the exercise the skill README asks for and that has never been done | E8: Test | F8: PLAN §4 Phase 0 | G8: T-006 | H8: 0.5 | I8: Opus 5 | J8: Complete | K8: 1 | L8: 46284 | M8: 46284 | N8: 0.25 | O8: Done. Install-TemplateDatabase.ps1 -VerifyIdempotent exited 0. A difflib comparison of pass 1 against pass 2 shows the only difference is the one-time verification section appended after pass 2: no Creating, Setting or Transferring lines anywhere in the re-run. State converges. The DDL event trail does not, and that is a different claim: each pass adds about 45 rows (114 -> 204 over two passes) because CREATE OR ALTER and the unconditional GRANT/DENY statements each raise a DDL event whether or not anything differed. BL-016.
A9: T-008 | B9: 0 Foundations | C9: 005_schemas_and_roles.sql | D9: Create rlsBypassRole; document who may be a member and the approval path | E9: Script | F9: DES §10.5 | G9: T-002 | H9: 0.5 | I9: Opus 5 | J9: Complete | K9: 1 | L9: 46284 | M9: 46284 | N9: 0.5 | O9: rlsBypassRole created in database/005_schemas_and_roles.sql section 3. Membership policy written out in section 4 as four numbered rules, and the closing report lists every member by name with a REVIEW severity so a privileged group nobody enumerates cannot quietly grow.
A10: T-009 | B10: 0 Foundations | C10: 000_prerequisites.sql | D10: Write the prerequisite/assertion script: target database check, compatibility level, database options | E10: Script | F10: DES §21.1 | G10: T-001 | H10: 0.5 | I10: Opus 5 | J10: Complete | K10: 1 | L10: 46284 | M10: 46284 | O10: database/000_prerequisites.sql. Asserts the server version (hard floor at major 16, warning above), creates the database if absent, sets compatibility level 160, READ_COMMITTED_SNAPSHOT, PAGE_VERIFY CHECKSUM and AUTO_CLOSE OFF, each guarded. Passes the convention gate.
A11: T-010 | B11: 0 Foundations | C11: 005_schemas_and_roles.sql | D11: Write schema creation for auth, logs, config, util with ownership to dbo; create the four roles guarded on existence | E11: Script | F11: DES §21.1 | G11: T-009 | H11: 0.75 | I11: Opus 5 | J11: Complete | K11: 1 | L11: 46284 | M11: 46284 | O11: database/005_schemas_and_roles.sql. Four schemas, ownership forced to dbo, four roles, and a closing report naming every schema owner and role member. Passes the convention gate.
A12: T-011 | B12: 0 Foundations | C12: (deployment runner) | D12: Establish the deployment runner: ordered execution, sqlcmd -I -C, -v DbName= on every installer, non-zero exit on failure | E12: Environment | F12: DES §21.1 | G12: T-010 | H12: 1 | I12: Opus 5 | J12: Complete | K12: 1 | L12: 46284 | M12: 46284 | N12: 1 | O12: Done. First execution of the runner, ever, and it ran correctly end to end: ordered manifest, sqlcmd -I -C -b -v DbName= on every installer, transcript to database/_logs/, and 090 skipped with its named reason while auth.Tenant is absent rather than failing the run. -VerifyIdempotent put both passes in one transcript. No change to the script was needed. AMENDED IN PHASE 1: the skip reason above named auth.Tenant, and that became wrong the moment 030_auth_tenant.sql created it. The probe tested one of the two tables 090_dbo_application.sql asserts, so it would have answered YES while the answer was 'some', and the deployment would have failed under -b at the exact moment Phase 1 succeeded. Test-AuthSchemaPresent now tests auth.Tenant AND auth.UserProfile, and the skip names auth.UserProfile -- BL-023.
A13: T-012 | B13: 0 Foundations | C13: ponytail-sql-objects | D13: De-reference the conventions skill: remove other projects' script names, database names, server names and logins; keep the worked examples and label them as the skill's own | E13: Documentation | F13: PLAN §6 | H13: 0.75 | I13: Opus 5 | J13: Complete | K13: 1 | L13: 46284 | M13: 46284 | O13: Skill de-referenced in the previous pass: foreign script paths, borrowed object names and the 'what this name used to be' archaeology all removed; worked examples kept and relabelled as the skill's own. The rules themselves were not touched.
A14: T-013 | B14: 0 Foundations | C14: Build Log | D14: Record every divergence found in Phase 0 against the skill's stated behaviour | E14: Documentation | F14: PLAN §10 | G14: T-007 | H14: 0.25 | I14: Opus 5 | J14: Complete | K14: 1 | L14: 46284 | M14: 46284 | N14: 0.25 | O14: Build Log entries BL-009 through BL-018 in build-and-traceability.xlsx. BL-014 ("nothing has ever been executed") is closed out by the first real deployment, and BL-015 through BL-018 record what that deployment found. Actual Days is filled only for the Phase 0 tasks executed against the server; the authoring tasks T-009 through T-013 were not separately timed.
A15: T-014 | B15: 1 Tenancy | C15: 030_auth_tenant.sql | D15: auth.Application — table, indexes, descriptions | E15: Table | F15: DES §15.2, D-09 | G15: T-010 | H15: 0.5 | I15: Opus 5 | J15: Complete | K15: 1 | L15: 46284 | M15: 46284 | N15: 0.1 | O15: database/030_auth_tenant.sql section 1. ApplicationCode unique where IsDeleted = 0, the seven audit columns, descriptions on the table and every column. It is what lets several independent tenant trees coexist in one database, which is the only way to test that a scope expressed at one root cannot reach another -- and the three variant trees of T-022 are three rows here, not three databases.
A16: T-015 | B16: 1 Tenancy | C16: 030_auth_tenant.sql | D16: auth.TenantType — table and seven seeded types | E16: Table | F16: DES §5.2 | G16: T-014 | H16: 0.5 | I16: Opus 5 | J16: Complete | K16: 1 | L16: 46284 | M16: 46284 | N16: 0.1 | O16: database/030_auth_tenant.sql section 2. The seven types are seeded by MERGE in THIS file rather than in 115_seed_reference_data.sql, because auth.Tenant's composite foreign key needs them before any tenant row can exist -- BL-021, and 115 must not re-seed them. _tests/020 asserts that all seven are exercised, which is how the three variant shapes were chosen rather than invented.
A17: T-016 | B17: 1 Tenancy | C17: 030_auth_tenant.sql | D17: auth.Tenant — table, self-referencing FK, CK_auth_Tenant_RootHasNoParent, filtered unique keys | E17: Table | F17: DES §15.2, INV-02 | G17: T-015 | H17: 1 | I17: Opus 5 | J17: Complete | K17: 1 | L17: 46284 | M17: 46284 | N17: 0.2 | O17: database/030_auth_tenant.sql section 3. Self-referencing FK, CK_auth_Tenant_RootHasNoParent, CK_auth_Tenant_NotOwnParent, CK_auth_Tenant_TenantCode, and two filtered unique indexes -- UX_auth_Tenant_ApplicationCode and UX_auth_Tenant_ApplicationRoot, the latter being the half of INV-02 a constraint can enforce. Carries a denormalised TenantTypeCode proved by a composite FK against an unfiltered UNIQUE: reaching the code through a scalar function was tried and MEASURED to break re-runnability at error 3729 -- BL-019.
A18: T-017 | B18: 1 Tenancy | C18: 030_auth_tenant.sql | D18: auth.TenantClosure — table with depth-0 self rows, PK on the pair | E18: Table | F18: DES §5.3 | G18: T-016 | H18: 0.5 | I18: Opus 5 | J18: Complete | K18: 1 | L18: 46284 | M18: 46284 | N18: 0.1 | O18: database/030_auth_tenant.sql section 4. PK on (AncestorTenantId, DescendantTenantId), a covering index on the descendant, and a depth-0 self row for every tenant. It deliberately does NOT filter soft-deleted tenants -- BL-020. A closure built over live rows only would drop a deleted mid-tree tenant from its descendants' ancestor set, and auth.udfIsTenantUsable would then fail OPEN for every program beneath it.
A19: T-018 | B19: 1 Tenancy | C19: 125_auth_tenant_procedures.sql | D19: auth.uspRebuildTenantClosure — full rebuild in one transaction, idempotent | E19: Procedure | F19: DES §5.3 | G19: T-017 | H19: 1 | I19: Opus 5 | J19: Complete | K19: 1 | L19: 46284 | M19: 46284 | N19: 0.2 | O19: database/125_auth_tenant_procedures.sql section 1. Parameterless whole-table rebuild: a recursive CTE over the parent edges into one MERGE, in one transaction, under OPTION (MAXRECURSION 100). No hard delete anywhere -- a pair the new shape no longer needs is soft-deleted and kept. The only Phase 1 procedure that is callable today, because it takes no session token and demands no permission; the fixtures use it. _tests/030 proves it correct after a re-parenting, silent on a second run, and loud on a cycle.
A20: T-019 | B20: 1 Tenancy | C20: 100_auth_functions.sql | D20: auth.udfIsTenantUsable — tenant and every ancestor active and not deleted | E20: Function | F20: DES §5.4 | G20: T-017 | H20: 0.5 | I20: Opus 5 | J20: Complete | K20: 1 | L20: 46284 | M20: 46284 | N20: 0.1 | O20: database/100_auth_functions.sql section 1. One RETURN of a CASE over two EXISTS so Froid inlines it, and no SCHEMABINDING -- this design schema-binds only the three RLS predicates. Fails closed three ways: an absent tenant, an unbuilt closure and a NULL argument all return 0. Two of the three are asserted in the script's own closing report, so the claim is re-checked on every deployment rather than resting in a comment.
A21: T-020 | B21: 1 Tenancy | C21: 095_auth_views.sql | D21: auth.vwTenantHierarchy — full path from root, depth, type label | E21: View | F21: DES §15.6 | G21: T-018 | H21: 0.5 | I21: Opus 5 | J21: Complete | K21: 1 | L21: 46284 | M21: 46284 | N21: 0.1 | O21: database/095_auth_views.sql. Recursive CTE giving TenantPath, Depth, the type label and AnyAncestorInactive. It installs BEFORE 100_auth_functions.sql and therefore cannot call auth.udfIsTenantUsable: a view resolves names at CREATE time, where a procedure gets deferred resolution. AnyAncestorInactive is documented as NOT a usability verdict for exactly that reason -- the verdict has one definition and it is the function, which uspGetTenantTree calls per node.
A22: T-021 | B22: 1 Tenancy | C22: 125_auth_tenant_procedures.sql | D22: uspCreateTenant, uspUpdateTenant, uspDeactivateTenant, uspGetTenantTree — each calling the closure rebuild | E22: Procedure | F22: DES §5.3 | G22: T-018 | H22: 1.5 | I22: Opus 5 | J22: Complete | K22: 1 | L22: 46284 | M22: 46284 | N22: 0.25 | O22: database/125_auth_tenant_procedures.sql sections 2-5. uspCreateTenant, uspUpdateTenant and uspDeactivateTenant carry the full rule 8 instrumentation including the resurrection block; uspGetTenantTree is error-only. uspUpdateTenant refuses a move beneath the tenant's own descendant by reading the closure (50095) and demands Tenant.Update at the new parent as well as at the tenant. All four INSTALL today and cannot be CALLED until Phase 3 -- they reference auth.uspSetSessionContext and auth.uspDemandPermission, and a call before those exist fails with 2812. A conditional gate around the permission demands was rejected: that is finding F-07's shape, where a check skipped when its dependency is absent becomes a check that is skipped.
A23: T-022 | B23: 1 Tenancy | C23: database/_tests/020_tenancy_variant_trees.sql | D23: Build all three variant tenant trees from script | E23: Test | F23: DES §17 | G23: T-021 | H23: 1 | I23: Opus 5 | J23: Complete | K23: 1 | L23: 46284 | M23: 46284 | N23: 0.2 | O23: Three applications and 23 tenants, MERGE throughout so it converges on a populated database. It writes auth.Tenant directly rather than calling auth.uspCreateTenant -- 2812 today, and the three ROOTS could never go through it in any case, because it refuses roots by design (50094, INV-02). Because the MERGE restates every parent it also undoes what T-023 moves, which is what lets T-023 be unconditional. Verified: 4/9/10 tenants, closure 7/27/26 = SUM (Depth + 1) per application, all seven tenant types used exactly once, and no closure pair crossing an application.
A24: T-023 | B24: 1 Tenancy | C24: database/_tests/030_tenancy_closure_reparent.sql | D24: Re-parent a populated subtree and assert the closure is still correct — the case an incremental algorithm gets wrong | E24: Test | F24: DES §5.3 | G24: T-022 | H24: 0.5 | I24: Opus 5 | J24: Complete | K24: 1 | L24: 46284 | M24: 46284 | N24: 0.1 | O24: Three movements on VARIANT2 -- deepen, re-root, restore -- chosen to exercise the three MERGE branches. The re-root retires four pairs, two of them for a grandchild nothing wrote to: THE CASE AN INCREMENTAL ALGORITHM GETS WRONG. The round trip is identical to the baseline on (ancestor, descendant, depth), and a second rebuild is identical including auditModifiedDateUtc -- a stronger claim than 'same answer', because it rules out a MERGE that rewrites every row to the value it already held and destroys the audit trail. Also proves that a cycle raises 530, leaves the closure intact, and is recorded in logs.ExecutionLog with ReCreatedAfterRollback = 0.
A25: T-024 | B25: 1 Tenancy | C25: 030_auth_tenant.sql | D25: MS_Description on every Phase 1 table and column | E25: Documentation | F25: Conventions rule 4 | G25: T-018 | H25: 0.5 | I25: Opus 5 | J25: Complete | K25: 1 | L25: 46284 | M25: 46284 | N25: 0.05 | O25: database/030_auth_tenant.sql section 6, with the matching sections of 095, 100 and 125. The deployment transcript reports 47 of 47 columns carrying MS_Description and 5 of 5 procedures carrying a description. The counts are computed by the scripts themselves against sys.columns and sys.extended_properties, so a column added later without a description appears in the next transcript rather than waiting to be noticed by a reader comparing two lists.
... A102: T-102 | B102: 7 Demo domain | C102: 180_dbo_application_procedures.sql | D102: Demo domain CRUD procedures as the reference implementation of the DES §14 calling contract | E102: Procedure | F102: DES §14 | G102: T-098 | H102: 2 | I102: Opus 5 | J102: Complete | K102: 1 | L102: 46285 | M102: 46285 | N102: 1.1 | O102: database/180_dbo_application_procedures.sql: the demo domain CRUD procedures, as the reference implementation of the section 14 calling contract -- @SessionTokenHash first, context set, permission demanded, rule 8 TRY/CATCH, instrumentation inside the transaction. It installs at manifest step 35, BEFORE 120_rls_policy.sql, which looks backwards and is right: deferred name resolution lets a procedure compile without its policy, but a bound policy freezes the shape of dbo.CaseFile and the schema-bound predicates (error 3729). The cost is a documented one-step window where these procedures enforce authorization without row security (BL-058). Raises E-50010 on an attempt to change an immutable approval, E-50011 on a TenantId change, E-50207 on a @Status outside the six the check constraint allows, and E-50202 to E-50206 across the surface. E-50203 covers two sites in one rule and forced a consequence into the open: APPROVAL IS NOT DELEGABLE ACROSS TENANTS, because FK_dbo_CaseFile_ApprovedBy_Tenant is on the composite pair -- an administrator with Data.Approve over a subtree must still switch to a profile at the row's own tenant. That is G-40, and G-36 is the second half of the bill.
A103: T-103 | B103: 8 Verification | C103: 170_permissions.sql | D103: Object-level EXECUTE grants per procedure; assert applicationRole holds no table permission on SCHEMA::auth | E103: Script | F103: DES §19.3, INV-11 | G103: T-099 | H103: 1 | I103: Opus 5 | J103: Not started | K103: 0
A104: T-104 | B104: 8 Verification | C104: 950_verify_deployment.sql | D104: Write every assertion listed in DES §21.4; exit non-zero on failure | E104: Script | F104: DES §21.4 | G104: T-100 | H104: 2 | I104: Opus 5 | J104: Not started | K104: 0
A105: T-105 | B105: 8 Verification | C105: (deployment) | D105: Two consecutive clean deployments onto an empty database, second reporting no change | E105: Test | F105: PLAN §4 Phase 8 | G105: T-101 | H105: 1 | I105: Opus 5 | J105: Not started | K105: 0
A106: T-106 | B106: 8 Verification | C106: Build Log | D106: Fill in every divergence between plan and code, with the reason | E106: Documentation | F106: PLAN §10 | G106: T-102 | H106: 0.75 | I106: Opus 5 | J106: Not started | K106: 0
A107: T-107 | B107: 8 Verification | C107: gaps.xlsx | D107: Close out: which gaps closed, which remain, which were added during build | E107: Documentation | F107: PLAN §10 | G107: T-102 | H107: 0.5 | I107: Opus 5 | J107: Not started | K107: 0
A108: T-108 | B108: 8 Verification | C108: build-and-traceability.xlsx | D108: Reconcile Traceability — every design section resolves to an artefact | E108: Documentation | F108: PLAN §10 | G108: T-102 | H108: 0.75 | I108: Opus 5 | J108: Not started | K108: 0
A109: T-109 | B109: 8 Verification | C109: 00-documentation-index.md | D109: Final pass on the documentation index | E109: Documentation | F109: Deliverable 7 | G109: T-104 | H109: 0.25 | I109: Opus 5 | J109: Not started | K109: 0
A110: T-110 | B110: 8 Verification | C110: (handoff) | D110: Template handoff: a reader who was not here deploys it and extends it | E110: Documentation | F110: PLAN §4 Phase 8 | G110: T-105 | H110: 0.75 | I110: Opus 5 | J110: Not started | K110: 0
A111: T-111 | B111: 0 Foundations | C111: _tests/010_phase0_instrumentation.sql | D111: Prove the rule 8 instrumentation end to end: an instrumented procedure writes to logs.ExecutionLog on success, on a flat failure, and on a failure inside a caller's open transaction | E111: Test | F111: PLAN §4 Phase 0 | G111: T-005 | H111: 0.5 | I111: Opus 5 | J111: Complete | K111: 1 | L111: 46284 | M111: 46284 | N111: 0.5 | O111: database/_tests/010_phase0_instrumentation.sql. Creates util.Phase0ProbeTarget and util.uspPhase0Probe to the conventions and exercises three paths. Recorded: a successful call (Successful = 1, 8 ms, "1 probe row(s) merged."), a flat failure (Successful = 0, ErrorNumber 50099, ReCreatedAfterRollback = 0), and a failure inside a caller's open transaction (Successful = 0, 50099, ReCreatedAfterRollback = 1) with a gap in the identity sequence where the rolled-back start row had been -- observable proof of the re-creation path, which no other placement exercises. Deliberately NOT in the install manifest: it creates test fixtures a cloning project should not inherit. Re-runnable -- the second run incremented ProbeCount rather than inserting again.
A112: T-112 | B112: 2 Identity | C112: 112_auth_mfa_procedures.sql | D112: The MFA enrolment surface: enrol, confirm, issue recovery codes, re-key -- and the bootstrap that lets an account refused for want of a factor obtain its first one | E112: Procedure | F112: DES §6.2, §6.4, G-07, T-041 | G112: T-041 | H112: 1 | I112: Opus 5 | J112: Complete | K112: 1 | L112: 46285 | M112: 46285 | N112: 0.8 | O112: Added on 2026-09-20, after the G-07 decision made it writable. NOT in PLAN-AUTH-001: the plan had T-041 as an Environment task -- choose a key and record the convention -- and assumed enrolment fell out of it. It does not. Four procedures in database/112_auth_mfa_procedures.sql: auth.uspEnrolMfaFactor, uspConfirmMfaFactor, uspIssueMfaRecoveryCodes, uspRotateMfaFactorKey. Kept OUT of 110_auth_authn_procedures.sql deliberately: 110 answers 'can this deployment sign anybody in' and 112 answers 'can this deployment enrol anybody', and the two have different threat models. The hard part was the bootstrap paradox -- an account under a policy requiring MFA with no factor cannot sign in, so it has no session to enrol with. Solved with auth.udfResolveEnrolmentActor, which accepts ONLY a LoginAttempt the database itself refused with FailureReason 'MfaRequired' and PasswordVerified = 1, inside Authn.MfaEnrolmentWindowSeconds. That grants an identity and not a permission: E-50119 still refuses to touch an account that already holds a confirmed factor, so the window is a route to a FIRST factor only, and setting it to 0 closes the route with no code change. New error numbers 50117-50123; new event type 'MfaEnrolmentRefused' in 085_logs_auth_tables.sql. Verified by _tests/040 section 12, eleven observations, where authtest.frank enrols from his own E-50109 refusal and completes a sign-in. One defect was found BY that section and fixed: uspConfirmMfaFactor and uspRotateMfaFactorKey each tested existence by whether a SELECT had assigned an OUTPUT parameter, which a caller re-using one variable defeats -- for the rotation sweep that is the INTENDED caller. Both now clear their outputs first. BL-035.
A113: T-113 | B113: 6 Administration | C113: 110_auth_authn_procedures.sql; 025_config_tables.sql | D113: The credential write surface and its lifecycle: uspSetPassword, uspGetPasswordChangeContext, uspChangePassword, uspExpireCredentials, and the three settings that govern them | E113: Procedure | F113: DES §6.3, §7.1, §16.2; D-08; G-42, G-12 | G113: T-034 | H113: 1.5 | I113: Opus 5 | J113: Complete | K113: 1 | L113: 46286 | M113: 46286 | N113: 1.3 | O113: Added 2026-09-21 to close G-42 and G-12, neither of which is in PLAN-AUTH-001: both were filed while writing the M4 handoff. FOUR PROCEDURES RATHER THAN THE TWO G-42 NAMED. The two extra are the interesting ones. uspGetPasswordChangeContext exists because D-08 has a consequence nobody had written down: if the database never receives a password it cannot COMPARE one against a stored PHC string either, because that needs the hashing parameters and a per-verifier salt -- so the reuse check had to become a read procedure plus an argument, exactly as sign-in is uspGetLoginVerifier plus a verdict. uspExpireCredentials is G-12 s sweep, folded in here because a password that cannot be set cannot usefully expire, which is the dependency the gap register recorded before the work started. Five numbers: E-50220 to E-50224. Authn.PasswordLifetimeDays ships at 0 -- no expiry -- deliberately: the mechanism is delivered and the policy is the deployment s. BL-067.
A114: T-114 | B114: 6 Administration | C114: 125_auth_tenant_procedures.sql; 035_auth_tenant_policy.sql | D114: uspSetTenantAuthenticationPolicy and uspSetTenantDefaultRoles, with the trusted-issuer list and the step-up default they carry | E114: Procedure | F114: DES §7.2, §7.3, §8.5, §11.5, §12.3; INV-04; G-43, G-21, G-30 | G114: T-018 | H114: 2 | I114: Opus 5 | J114: Complete | K114: 1 | L114: 46286 | M114: 46286 | N114: 1.8 | O114: Added 2026-09-21. THREE GAPS IN ONE TASK, AND NOT BY CONVENIENCE: G-30 needed a policy WRITER to seed a default into, and G-21 needed one to write a trusted-issuer list with, so G-43 had to go first and the other two fell out of it. auth.TenantTrustedIssuer went into 035 rather than 045 because it is policy and not identity. TWO DEPARTURES FROM G-43, both in BL-068: the permission is Tenant.Update (there is no Tenant.Manage in Appendix A, and Config.Manage would have made a per-tenant screen a platform-administrator screen), with Authz.RoleAssign added to the default-roles writer because a default-role list is a standing grant rather than a label; and the validation is MERGE THEN VALIDATE THE ROW rather than validate the arguments, which is the only shape that survives every argument being optional. E-50097, E-50098, E-50124 and E-50180, all raised ahead of BEGIN TRANSACTION so a test can probe them against a real tenant and leave no row behind. Filed G-44 on the way out: nothing DELETES a policy row.
A115: T-115 | B115: 6 Administration | C115: 155_auth_registration_procedures.sql; 080_auth_registration.sql; 025_config_tables.sql | D115: auth.RegistrationAttempt and uspRecordRegistrationAttempt -- the per-address registration throttle, and the decision G-24 demanded be taken either way | E115: Procedure | F115: DES §16.1, §16.4, §11.5; G-24, G-06 | G115: T-087 | H115: 0.75 | I115: Opus 5 | J115: Complete | K115: 1 | L115: 46286 | M115: 46286 | N115: 0.7 | O115: Added 2026-09-21. G-24 asked for a DECISION -- build the counter, or comment the ClientAddress column to say the edge owns it -- and the counter was built. The verdict comes back as an @AddressThrottled OUTPUT parameter rather than from a separate predicate function: ONE ROUND TRIP, so the count and the decision cannot disagree and no caller can record without checking. The arrival is recorded BEFORE any other validation, which costs a row per malformed request and is the point, because a malformed request is the cheapest flood to generate. One budget across both public forms. THE TASK DID NOT CLOSE G-06 AND SAYS SO: a counter behind an unlimited public form is a control an attacker pays for once per address, and the two obligations that remain -- edge rate limiting and a challenge on the form -- are on the far side of a network boundary. G-06 still blocks Variant 3 go-live. BL-070.
A116: T-116 | B116: 6 Administration | C116: 115_seed_reference_data.sql; 150_auth_query_procedures.sql | D116: Ui.CatalogueVersion -- a digest of the element catalogue that the seed recomputes and uspGetNavigationForProfile refuses a mismatch against | E116: Procedure | F116: DES §13.1; G-18; UIH-AUTH-001 §4.2, §10 | G116: T-084 | H116: 0.75 | I116: Opus 5 | J116: Complete | K116: 1 | L116: 46286 | M116: 46286 | N116: 0.9 | O116: Added 2026-09-21. THE DATABASE RAISES THE MISMATCH, which is a departure from what G-18 proposed and is the whole value of the task: the gap asked the APPLICATION to assert the version at start-up, which leaves the control with the party whose defect it catches, and start-up is the wrong moment because a catalogue can be extended while an application is running. E-50230, checked before session resolution. The digest covers (ElementCode, PermissionCode, AccessMode) and excludes labels, sort orders and parentage, so the stamp tracks the interface and not the presentation. This is the one row in config.ApplicationSetting that 115 OVERWRITES on a match, against that file s own rule, because it is a fact about the catalogue rather than an operator s tuning. A blank argument is refused and an omitted one is not -- UI-43 is the row that tells a UI project why that matters. BL-069.
...

Sheet Phase Summary
A1: Phase roll-up — every figure is a formula over the Tasks sheet
A3: Phase | B3: Tasks | C3: Not started | D3: In progress | E3: Blocked | F3: In review | G3: Complete | H3: Deferred | I3: Est. Days | J3: Actual Days | K3: Variance | L3: % Complete
A4: 0 Foundations | B4: =COUNTIF(Tasks!$B$2:$B$400,$A4) | C4: =COUNTIFS(Tasks!$B$2:$B$400,$A4,Tasks!$J$2:$J$400,"Not started") | D4: =COUNTIFS(Tasks!$B$2:$B$400,$A4,Tasks!$J$2:$J$400,"In progress") | E4: =COUNTIFS(Tasks!$B$2:$B$400,$A4,Tasks!$J$2:$J$400,"Blocked") | F4: =COUNTIFS(Tasks!$B$2:$B$400,$A4,Tasks!$J$2:$J$400,"In review") | G4: =COUNTIFS(Tasks!$B$2:$B$400,$A4,Tasks!$J$2:$J$400,"Complete") | H4: =COUNTIFS(Tasks!$B$2:$B$400,$A4,Tasks!$J$2:$J$400,"Deferred") | I4: =SUMIF(Tasks!$B$2:$B$400,$A4,Tasks!$H$2:$H$400) | J4: =SUMIF(Tasks!$B$2:$B$400,$A4,Tasks!$N$2:$N$400) | K4: =IF(J4=0,"",J4-I4) | L4: =IFERROR(G4/B4,0)
A5: 1 Tenancy | B5: =COUNTIF(Tasks!$B$2:$B$400,$A5) | C5: =COUNTIFS(Tasks!$B$2:$B$400,$A5,Tasks!$J$2:$J$400,"Not started") | D5: =COUNTIFS(Tasks!$B$2:$B$400,$A5,Tasks!$J$2:$J$400,"In progress") | E5: =COUNTIFS(Tasks!$B$2:$B$400,$A5,Tasks!$J$2:$J$400,"Blocked") | F5: =COUNTIFS(Tasks!$B$2:$B$400,$A5,Tasks!$J$2:$J$400,"In review") | G5: =COUNTIFS(Tasks!$B$2:$B$400,$A5,Tasks!$J$2:$J$400,"Complete") | H5: =COUNTIFS(Tasks!$B$2:$B$400,$A5,Tasks!$J$2:$J$400,"Deferred") | I5: =SUMIF(Tasks!$B$2:$B$400,$A5,Tasks!$H$2:$H$400) | J5: =SUMIF(Tasks!$B$2:$B$400,$A5,Tasks!$N$2:$N$400) | K5: =IF(J5=0,"",J5-I5) | L5: =IFERROR(G5/B5,0)
A6: 2 Identity | B6: =COUNTIF(Tasks!$B$2:$B$400,$A6) | C6: =COUNTIFS(Tasks!$B$2:$B$400,$A6,Tasks!$J$2:$J$400,"Not started") | D6: =COUNTIFS(Tasks!$B$2:$B$400,$A6,Tasks!$J$2:$J$400,"In progress") | E6: =COUNTIFS(Tasks!$B$2:$B$400,$A6,Tasks!$J$2:$J$400,"Blocked") | F6: =COUNTIFS(Tasks!$B$2:$B$400,$A6,Tasks!$J$2:$J$400,"In review") | G6: =COUNTIFS(Tasks!$B$2:$B$400,$A6,Tasks!$J$2:$J$400,"Complete") | H6: =COUNTIFS(Tasks!$B$2:$B$400,$A6,Tasks!$J$2:$J$400,"Deferred") | I6: =SUMIF(Tasks!$B$2:$B$400,$A6,Tasks!$H$2:$H$400) | J6: =SUMIF(Tasks!$B$2:$B$400,$A6,Tasks!$N$2:$N$400) | K6: =IF(J6=0,"",J6-I6) | L6: =IFERROR(G6/B6,0)
A7: 3 Authorization | B7: =COUNTIF(Tasks!$B$2:$B$400,$A7) | C7: =COUNTIFS(Tasks!$B$2:$B$400,$A7,Tasks!$J$2:$J$400,"Not started") | D7: =COUNTIFS(Tasks!$B$2:$B$400,$A7,Tasks!$J$2:$J$400,"In progress") | E7: =COUNTIFS(Tasks!$B$2:$B$400,$A7,Tasks!$J$2:$J$400,"Blocked") | F7: =COUNTIFS(Tasks!$B$2:$B$400,$A7,Tasks!$J$2:$J$400,"In review") | G7: =COUNTIFS(Tasks!$B$2:$B$400,$A7,Tasks!$J$2:$J$400,"Complete") | H7: =COUNTIFS(Tasks!$B$2:$B$400,$A7,Tasks!$J$2:$J$400,"Deferred") | I7: =SUMIF(Tasks!$B$2:$B$400,$A7,Tasks!$H$2:$H$400) | J7: =SUMIF(Tasks!$B$2:$B$400,$A7,Tasks!$N$2:$N$400) | K7: =IF(J7=0,"",J7-I7) | L7: =IFERROR(G7/B7,0)
A8: 4 Row security | B8: =COUNTIF(Tasks!$B$2:$B$400,$A8) | C8: =COUNTIFS(Tasks!$B$2:$B$400,$A8,Tasks!$J$2:$J$400,"Not started") | D8: =COUNTIFS(Tasks!$B$2:$B$400,$A8,Tasks!$J$2:$J$400,"In progress") | E8: =COUNTIFS(Tasks!$B$2:$B$400,$A8,Tasks!$J$2:$J$400,"Blocked") | F8: =COUNTIFS(Tasks!$B$2:$B$400,$A8,Tasks!$J$2:$J$400,"In review") | G8: =COUNTIFS(Tasks!$B$2:$B$400,$A8,Tasks!$J$2:$J$400,"Complete") | H8: =COUNTIFS(Tasks!$B$2:$B$400,$A8,Tasks!$J$2:$J$400,"Deferred") | I8: =SUMIF(Tasks!$B$2:$B$400,$A8,Tasks!$H$2:$H$400) | J8: =SUMIF(Tasks!$B$2:$B$400,$A8,Tasks!$N$2:$N$400) | K8: =IF(J8=0,"",J8-I8) | L8: =IFERROR(G8/B8,0)
A9: 5 Performance | B9: =COUNTIF(Tasks!$B$2:$B$400,$A9) | C9: =COUNTIFS(Tasks!$B$2:$B$400,$A9,Tasks!$J$2:$J$400,"Not started") | D9: =COUNTIFS(Tasks!$B$2:$B$400,$A9,Tasks!$J$2:$J$400,"In progress") | E9: =COUNTIFS(Tasks!$B$2:$B$400,$A9,Tasks!$J$2:$J$400,"Blocked") | F9: =COUNTIFS(Tasks!$B$2:$B$400,$A9,Tasks!$J$2:$J$400,"In review") | G9: =COUNTIFS(Tasks!$B$2:$B$400,$A9,Tasks!$J$2:$J$400,"Complete") | H9: =COUNTIFS(Tasks!$B$2:$B$400,$A9,Tasks!$J$2:$J$400,"Deferred") | I9: =SUMIF(Tasks!$B$2:$B$400,$A9,Tasks!$H$2:$H$400) | J9: =SUMIF(Tasks!$B$2:$B$400,$A9,Tasks!$N$2:$N$400) | K9: =IF(J9=0,"",J9-I9) | L9: =IFERROR(G9/B9,0)
A10: 6 Administration | B10: =COUNTIF(Tasks!$B$2:$B$400,$A10) | C10: =COUNTIFS(Tasks!$B$2:$B$400,$A10,Tasks!$J$2:$J$400,"Not started") | D10: =COUNTIFS(Tasks!$B$2:$B$400,$A10,Tasks!$J$2:$J$400,"In progress") | E10: =COUNTIFS(Tasks!$B$2:$B$400,$A10,Tasks!$J$2:$J$400,"Blocked") | F10: =COUNTIFS(Tasks!$B$2:$B$400,$A10,Tasks!$J$2:$J$400,"In review") | G10: =COUNTIFS(Tasks!$B$2:$B$400,$A10,Tasks!$J$2:$J$400,"Complete") | H10: =COUNTIFS(Tasks!$B$2:$B$400,$A10,Tasks!$J$2:$J$400,"Deferred") | I10: =SUMIF(Tasks!$B$2:$B$400,$A10,Tasks!$H$2:$H$400) | J10: =SUMIF(Tasks!$B$2:$B$400,$A10,Tasks!$N$2:$N$400) | K10: =IF(J10=0,"",J10-I10) | L10: =IFERROR(G10/B10,0)
A11: 7 Demo domain | B11: =COUNTIF(Tasks!$B$2:$B$400,$A11) | C11: =COUNTIFS(Tasks!$B$2:$B$400,$A11,Tasks!$J$2:$J$400,"Not started") | D11: =COUNTIFS(Tasks!$B$2:$B$400,$A11,Tasks!$J$2:$J$400,"In progress") | E11: =COUNTIFS(Tasks!$B$2:$B$400,$A11,Tasks!$J$2:$J$400,"Blocked") | F11: =COUNTIFS(Tasks!$B$2:$B$400,$A11,Tasks!$J$2:$J$400,"In review") | G11: =COUNTIFS(Tasks!$B$2:$B$400,$A11,Tasks!$J$2:$J$400,"Complete") | H11: =COUNTIFS(Tasks!$B$2:$B$400,$A11,Tasks!$J$2:$J$400,"Deferred") | I11: =SUMIF(Tasks!$B$2:$B$400,$A11,Tasks!$H$2:$H$400) | J11: =SUMIF(Tasks!$B$2:$B$400,$A11,Tasks!$N$2:$N$400) | K11: =IF(J11=0,"",J11-I11) | L11: =IFERROR(G11/B11,0)
A12: 8 Verification | B12: =COUNTIF(Tasks!$B$2:$B$400,$A12) | C12: =COUNTIFS(Tasks!$B$2:$B$400,$A12,Tasks!$J$2:$J$400,"Not started") | D12: =COUNTIFS(Tasks!$B$2:$B$400,$A12,Tasks!$J$2:$J$400,"In progress") | E12: =COUNTIFS(Tasks!$B$2:$B$400,$A12,Tasks!$J$2:$J$400,"Blocked") | F12: =COUNTIFS(Tasks!$B$2:$B$400,$A12,Tasks!$J$2:$J$400,"In review") | G12: =COUNTIFS(Tasks!$B$2:$B$400,$A12,Tasks!$J$2:$J$400,"Complete") | H12: =COUNTIFS(Tasks!$B$2:$B$400,$A12,Tasks!$J$2:$J$400,"Deferred") | I12: =SUMIF(Tasks!$B$2:$B$400,$A12,Tasks!$H$2:$H$400) | J12: =SUMIF(Tasks!$B$2:$B$400,$A12,Tasks!$N$2:$N$400) | K12: =IF(J12=0,"",J12-I12) | L12: =IFERROR(G12/B12,0)
A13: TOTAL | B13: =SUM(B4:B12) | C13: =SUM(C4:C12) | D13: =SUM(D4:D12) | E13: =SUM(E4:E12) | F13: =SUM(F4:F12) | G13: =SUM(G4:G12) | H13: =SUM(H4:H12) | I13: =SUM(I4:I12) | J13: =SUM(J4:J12) | K13: =IF(J13=0,"",J13-I13) | L13: =IFERROR(G13/B13,0)
A15: Estimates are planning figures from PLAN-AUTH-001 §4, to be re-based by the team after Phase 0. Enter Actual Days on the Tasks sheet; Variance and % Complete follow automatically. Phase 1's Actual Days are one working session's elapsed time apportioned across its eleven tasks in proportion to estimate: 1.5 days against 8.0 estimated. The per-task figures are therefore an allocation and not eleven independent measurements; only the phase total is measured. A team with a timesheet should overwrite them. The roll-up ranges run to row 130 rather than to the last task, so appended tasks are counted without the formulas having to be edited again -- they were edited on 2026-09-21, when T-113 to T-119 fell outside a range that stopped at row 112 and the Phase 6 totals quietly under-reported by seven tasks until somebody looked. T-113 TO T-119 ARE NOT IN PLAN-AUTH-001 EITHER: they close nine gaps.rows filed during Phases 5 to 7 and while writing the M4 handoff, so their 7.0 estimated days are this pass s own figures and not a re-based plan. 7.0 actual against 7.0 estimated, which is the first batch in this project to land on its estimate and is not a sign of skill -- the work was specified in the gap rows before it was started, and four of the seven still departed from what those rows proposed. T-120 AND T-121 ARE FILED UNDER PHASES 1 AND 4 AND NOT UNDER THE PASS THAT FOUND THEM, because a task belongs to the phase whose work it finishes and each of them fixes that phase's own exit-criteria test. Both are test defects, both were found by running the suite in the documented order rather than by reading anything, and both reported a correct database as broken -- which is why 0.7 actual days against 0.5 estimated is the cheapest entry in this workbook and the one most worth having.
A16: Milestones: M1 after Phase 0 · M2 after Phase 4 · M3 after Phase 5 (go/no-go on D-07) · M4 after Phase 6 (UI contract freeze) · M5 after Phase 8.

Sheet Legend
B2: How to use this workbook
B4: Implementation tracker for PLAN-AUTH-001, which implements DES-AUTH-001. One row per task, grouped by the nine phases of the plan. This is the living document of the project — the design and the plan are versioned, this changes daily.
B6: Which cells you edit
B7: On the Tasks sheet, the shaded columns in blue text are yours: Owner, Status, % Done, Started, Completed, Actual Days, and Notes / Blockers. Everything to their left comes from the plan and should change only when the plan changes.
B9: The Phase Summary sheet is entirely formulas. Do not type into it.
B11: Example of a completed row
B12: Below is what a filled-in row looks like. It is an illustration only and is not counted by the Phase Summary.
A14: Task ID | B14: Phase | C14: Artefact / Script | D14: Task | E14: Type | F14: Design Ref | G14: Depends On | H14: Est. Days | I14: Owner | J14: Status | K14: % Done | L14: Started | M14: Completed | N14: Actual Days | O14: Notes / Blockers
A15: T-017 | B15: 1 Tenancy | C15: 125_auth_tenant_procedures.sql | D15: auth.uspRebuildTenantClosure — full rebuild in one transaction, idempotent | E15: Procedure | F15: DES §5.3 | G15: T-016 | H15: 1 | I15: R. Sincero | J15: Complete | K15: 1 | L15: 2026-10-06 | M15: 2026-10-08 | N15: 1.5 | O15: Overran: the re-parenting test found the closure was not rebuilding depth-0 rows for the moved node.
A18: • Status values: Not started · In progress · Blocked · In review · Complete · Deferred.
A19: • A task stays In progress until it is genuinely finished. A task with a failing test is not Complete.
A20: • Blocked needs a reason in Notes / Blockers naming what would unblock it.
A21: • Design Ref points at DES-AUTH-001 (the design) or PLAN-AUTH-001 (this plan). G- and UI- codes point at the Gaps and UI Gotchas workbooks.
A22: • Depends On names the task that must finish first. It is advisory, not enforced.
B24: Why the task numbering skips T-045
B25: T-045 was 'table-valued parameter types for bulk role assignment' and has been DELETED, not re-scoped, because gap G-20 resolved the bulk payload as an NVARCHAR (MAX) JSON array shredded with OPENJSON and gated by ISJSON (@Payload, ARRAY) = 0. There is no type to create, so there is no task -- re-scoping it to 'do nothing' would leave a row somebody has to read before discovering it is empty. DES section 14.6 and section 8.2 carry the decision, E-50046 is the malformed-payload error, and BL-030 records the deletion. The Dapper note changed with it: serialise the list and pass a string, rather than build a DataTable.
A27: Why the task numbering ends at T-119, and why every task past T-110 was appended rather than inserted
A28: T-112 is the MFA enrolment surface, added on 2026-09-20 once gap G-07 was decided and appended rather than inserted next to T-041. The Phase Summary formulas read Tasks!$B$2:$B$112, so row 112 is the last row they count: inserting a row in the middle would have left them counting a range that no longer matches the sheet, and a roll-up that quietly under-counts a phase is worse than an ID out of sequence. The plan did not have this task because the plan expected enrolment to fall out of choosing a key. It did not: the key decision is one day of reading and the surface is four procedures with a bootstrap problem in the middle of it. T-113 TO T-119 WERE APPENDED THE SAME WAY ON 2026-09-21, for the same reason and with one correction. They close nine gap rows -- G-12, G-18, G-21, G-24, G-27, G-30, G-32, G-42 and G-43 -- none of which is in PLAN-AUTH-001, because all nine were filed during Phases 5 to 7 or while writing the M4 handoff. THE CORRECTION IS THE ONE THE PARAGRAPH ABOVE SHOULD HAVE MADE: appending kept the formulas VALID and did not keep them CORRECT. Tasks!$B$2:$B$112 stopped at what was then the last row, so the first appended row past it would have been counted nowhere -- Phase 6 would have under-reported by seven tasks and the roll-up would have looked healthy while doing it. The ranges now run to row 130, which is headroom rather than a fix: the rule is that the range must exceed the sheet, and a range that merely reaches it is a range that is one append away from lying. All seven are Phase 6 Administration, because that is the phase whose gaps they close, and grouping them there keeps the phase variance honest -- 7.0 days estimated against 7.0 actual, the first batch in this project to land on its estimate, which says more about the gap rows having specified the work than about anybody s judgement. Four of the seven departed from what those rows proposed anyway, and the departures are in BL-067 to BL-073.
A30: How to read Started and Completed on the rows closed so far
A31: Phases 0 to 7 were built and deployed against MDE-55TT2J4\testTemplate in a small number of sittings rather than over the calendar the estimates assume, so Started and Completed on those rows record the DATE THE WORK LANDED and not an elapsed span: every row from Phase 3 onward carries 2026-09-20 in both columns. Actual Days is still meaningful and is not the gap between those two dates -- it is effort in the same planning unit as Est. Days, so the Variance column on Phase Summary continues to mean what it means. A team working to a calendar should overwrite both dates with real ones. ONE SET OF ROWS DID NOT LAND ON testTemplate AT ALL. T-069 to T-073, the Phase 5 measurements, ran against a separate database, MDE-55TT2J4\testTemplateBoot, loaded with 1,050 tenants, 5,000 profiles and 200,000 case files. That separation is deliberate and worth keeping: a measurement fixture in the working database is a row somebody will eventually mistake for real. The consequence is that testTemplateBoot must be dropped and rebuilt before any further predicate measurement, because T-072 expanded it to 10,650 tenants and left it there. Actual Days from Phase 5 onward are per-task figures rather than an apportionment. Phases 5, 6 and 7 came in at 26.0 days of effort against the 35.5 the plan estimated for the same 34 tasks -- 3.8 against 6, 18.5 against 23.5 and 3.7 against 6. EXACTLY ONE TASK IN THE BATCH EXCEEDED ITS OWN ESTIMATE: T-094, the error catalogue, at 1.6 against 1, because the coverage report found the suite was crediting itself with residue and the fix was to measure the registry against sys.sql_modules rather than assert it. The other two largest actuals did NOT overrun and are recorded here only because their Notes are the ones worth reading -- T-087 at 1.5 (the registration procedures, the only unauthenticated writers in the database, which must therefore validate everything) and T-078 at 1.4 against 1.5 (the profile switch, which threw E-50022 on every call after succeeding). An earlier version of this note said "roughly 27 days" and called all three overruns; both halves were wrong, and a Legend that rounds its own roll-up is a Legend nobody can reconcile against Phase Summary.
